Workbook

Sheet 1. RAW DATA DUMP
B1: 60/40 Equity/Bond | C1: SG Trend | E1: date | F1: PX_OPEN | G1: PX_HIGH | H1: PX_LOW | I1: PX_LAST
A2: 21733 | B2: 100 | C2: 100 | E2: 35683 | F2: 1222.95 | G2: 1223.61 | H2: 1197.74 | I2: 1198.72
A3: 21734 | B3: 100 | C3: 100 | E3: 35684 | F3: 1199.71 | G3: 1201.67 | H3: 1179.41 | I3: 1189.88
A4: 21737 | B4: 100 | C4: 100 | E4: 35685 | F4: 1189.23 | G4: 1213.13 | H4: 1183.99 | I4: 1210.18
A5: 21738 | B5: 100 | C5: 100 | E5: 35688 | F5: 1211.17 | G5: 1218.04 | H5: 1204.29 | I5: 1207.24
A6: 21739 | B6: 100 | C6: 100 | E6: 35689 | F6: 1208.22 | G6: 1243.25 | H6: 1206.26 | I6: 1239.33
A7: 21740 | B7: 100 | C7: 100 | E7: 35690 | F7: 1236.71 | G7: 1247.51 | H7: 1234.09 | I7: 1238.67
A8: 21741 | B8: 100 | C8: 100 | E8: 35691 | F8: 1238.35 | G8: 1257.46 | H8: 1237.05 | I8: 1240.94
A9: 21744 | B9: 100 | C9: 100 | E9: 35692 | F9: 1240.94 | G9: 1248.06 | H9: 1234.78 | I9: 1245.15
A10: 21745 | B10: 100 | C10: 100 | E10: 35695 | F10: 1244.18 | G10: 1259.4 | H10: 1244.18 | I10: 1251.95
A11: 21746 | B11: 100 | C11: 100 | E11: 35696 | F11: 1250.66 | G11: 1253.25 | H11: 1239.32 | I11: 1246.44
A12: 21747 | B12: 100 | C12: 100 | E12: 35697 | F12: 1245.8 | G12: 1257.46 | H12: 1233.49 | I12: 1236.73
A13: 21748 | B13: 100 | C13: 100 | E13: 35698 | F13: 1235.76 | G13: 1240.61 | H13: 1225.07 | I13: 1226.36
... A7307: 31960 | B7307: 181.29205 | C7307: 100 | E7307: 46205 | F7307: 7536 | G7307: 7593.75 | H7307: 7479.5 | I7307: 7528.25
A7308: 31961 | B7308: 181.27945 | C7308: 100
A7309: 31964 | B7309: 181.06909 | C7309: 100
A7310: 31965 | B7310: 182.04822 | C7310: 100
A7311: 31966 | B7311: 182.13358 | C7311: 100
A7312: 31967 | B7312: 181.51911 | C7312: 100
A7313: 31968 | B7313: 182.21919 | C7313: 100
A7314: 31971 | B7314: 181.67024 | C7314: 100
A7315: 31972 | B7315: 182.98834 | C7315: 100
A7316: 31973 | B7316: 182.47329 | C7316: 100
A7317: 31974 | B7317: 183.43533 | C7317: 100
A7318: 31975 | B7318: 184.36802 | C7318: 100
A7319: 31978 | B7319: 182.91764 | C7319: 100
... A17487: 46212 | B17487: 1583.2134 | C17487: 100
A17488: 46213 | B17488: 1585.8244

Sheet 2. DATA_CLEAN
G3: Sorted New->Old
E5: Common dates | H5: 60/40 Equity/Bond | I5: SG Trend | J5: S&P
B6: 21733 | C6: 35683 | E6: {=_xlfn.UNIQUE(_xlfn._xlws.FILTER(B6:B17492,COUNTIF(C6:C17492,B6:B17492)>0,"No common dates"))} -> 35683 | G6: 46205 | H6: =VLOOKUP($G6,'1. RAW DATA DUMP'!$A:$I,2,FALSE) -> 1577.406 | I6: =VLOOKUP($G6,'1. RAW DATA DUMP'!$A:$I,3,FALSE) -> 100 | J6: =VLOOKUP($G6,'1. RAW DATA DUMP'!E:I,5,FALSE) -> 7528.25
B7: 21734 | C7: 35684 | E7: 35684 | G7: 46204 | H7: =VLOOKUP($G7,'1. RAW DATA DUMP'!$A:$I,2,FALSE) -> 1579.3234 | I7: =VLOOKUP($G7,'1. RAW DATA DUMP'!$A:$I,3,FALSE) -> 100 | J7: =VLOOKUP($G7,'1. RAW DATA DUMP'!E:I,5,FALSE) -> 7543.5
B8: 21737 | C8: 35685 | E8: 35685 | G8: 46203 | H8: =VLOOKUP($G8,'1. RAW DATA DUMP'!$A:$I,2,FALSE) -> 1581.7198 | I8: =VLOOKUP($G8,'1. RAW DATA DUMP'!$A:$I,3,FALSE) -> 100 | J8: =VLOOKUP($G8,'1. RAW DATA DUMP'!E:I,5,FALSE) -> 7548.25
B9: 21738 | C9: 35688 | E9: 35688 | G9: 46202 | H9: =VLOOKUP($G9,'1. RAW DATA DUMP'!$A:$I,2,FALSE) -> 1576.9274 | I9: =VLOOKUP($G9,'1. RAW DATA DUMP'!$A:$I,3,FALSE) -> 100 | J9: =VLOOKUP($G9,'1. RAW DATA DUMP'!E:I,5,FALSE) -> 7500.25
B10: 21739 | C10: 35689 | E10: 35689 | G10: 46199 | H10: =VLOOKUP($G10,'1. RAW DATA DUMP'!$A:$I,2,FALSE) -> 1564.2842 | I10: =VLOOKUP($G10,'1. RAW DATA DUMP'!$A:$I,3,FALSE) -> 100 | J10: =VLOOKUP($G10,'1. RAW DATA DUMP'!E:I,5,FALSE) -> 7401.75
B11: 21740 | C11: 35690 | E11: 35690 | G11: 46198 | H11: =VLOOKUP($G11,'1. RAW DATA DUMP'!$A:$I,2,FALSE) -> 1566.2251 | I11: =VLOOKUP($G11,'1. RAW DATA DUMP'!$A:$I,3,FALSE) -> 100 | J11: =VLOOKUP($G11,'1. RAW DATA DUMP'!E:I,5,FALSE) -> 7423.25
B12: 21741 | C12: 35691 | E12: 35691 | G12: 46197 | H12: =VLOOKUP($G12,'1. RAW DATA DUMP'!$A:$I,2,FALSE) -> 1566.392 | I12: =VLOOKUP($G12,'1. RAW DATA DUMP'!$A:$I,3,FALSE) -> 100 | J12: =VLOOKUP($G12,'1. RAW DATA DUMP'!E:I,5,FALSE) -> 7428.25
B13: 21744 | C13: 35692 | E13: 35692 | G13: 46196 | H13: =VLOOKUP($G13,'1. RAW DATA DUMP'!$A:$I,2,FALSE) -> 1564.3126 | I13: =VLOOKUP($G13,'1. RAW DATA DUMP'!$A:$I,3,FALSE) -> 100 | J13: =VLOOKUP($G13,'1. RAW DATA DUMP'!E:I,5,FALSE) -> 7437.5
B14: 21745 | C14: 35695 | E14: 35695 | G14: 46195 | H14: =VLOOKUP($G14,'1. RAW DATA DUMP'!$A:$I,2,FALSE) -> 1577.3211 | I14: =VLOOKUP($G14,'1. RAW DATA DUMP'!$A:$I,3,FALSE) -> 100 | J14: =VLOOKUP($G14,'1. RAW DATA DUMP'!E:I,5,FALSE) -> 7541.25
B15: 21746 | C15: 35696 | E15: 35696 | G15: 46191 | H15: =VLOOKUP($G15,'1. RAW DATA DUMP'!$A:$I,2,FALSE) -> 1583.2973 | I15: =VLOOKUP($G15,'1. RAW DATA DUMP'!$A:$I,3,FALSE) -> 100 | J15: =VLOOKUP($G15,'1. RAW DATA DUMP'!E:I,5,FALSE) -> 7570.75
B16: 21747 | C16: 35697 | E16: 35697 | G16: 46190 | H16: =VLOOKUP($G16,'1. RAW DATA DUMP'!$A:$I,2,FALSE) -> 1572.6278 | I16: =VLOOKUP($G16,'1. RAW DATA DUMP'!$A:$I,3,FALSE) -> 100 | J16: =VLOOKUP($G16,'1. RAW DATA DUMP'!E:I,5,FALSE) -> 7492.75
B17: 21748 | C17: 35698 | E17: 35698 | G17: 46189 | H17: =VLOOKUP($G17,'1. RAW DATA DUMP'!$A:$I,2,FALSE) -> 1587.1849 | I17: =VLOOKUP($G17,'1. RAW DATA DUMP'!$A:$I,3,FALSE) -> 100 | J17: =VLOOKUP($G17,'1. RAW DATA DUMP'!E:I,5,FALSE) -> 7587.61
B18: 21751 | C18: 35699 | E18: 35699 | G18: 46188 | H18: =VLOOKUP($G18,'1. RAW DATA DUMP'!$A:$I,2,FALSE) -> 1591.417 | I18: =VLOOKUP($G18,'1. RAW DATA DUMP'!$A:$I,3,FALSE) -> 100 | J18: =VLOOKUP($G18,'1. RAW DATA DUMP'!E:I,5,FALSE) -> 7630.76
... B6716: 31127 | C6716: 45342 | E6716: 45342 | G6716: 36525 | H6716: =VLOOKUP($G6716,'1. RAW DATA DUMP'!$A:$I,2,FALSE) -> 444.00454 | I6716: =VLOOKUP($G6716,'1. RAW DATA DUMP'!$A:$I,3,FALSE) -> 100 | J6716: =VLOOKUP($G6716,'1. RAW DATA DUMP'!E:I,5,FALSE) -> 1744.82
B6717: 31128 | C6717: 45343 | E6717: 45343
B6718: 31131 | C6718: 45344 | E6718: 45344
B6719: 31132 | C6719: 45345 | E6719: 45345
B6720: 31133 | C6720: 45348 | E6720: 45348
B6721: 31134 | C6721: 45349 | E6721: 45349
B6722: 31135 | C6722: 45350 | E6722: 45350
B6723: 31138 | C6723: 45351 | E6723: 45351
B6724: 31139 | C6724: 45352 | E6724: 45352
B6725: 31140 | C6725: 45355 | E6725: 45355
B6726: 31141 | C6726: 45356 | E6726: 45356
B6727: 31142 | C6727: 45357 | E6727: 45357
B6728: 31145 | C6728: 45358 | E6728: 45358
... B7311: 31960 | C7311: 46205 | E7311: 46205
B7312: 31961
B7313: 31964
B7314: 31965
B7315: 31966
B7316: 31967
B7317: 31968
B7318: 31971
B7319: 31972
B7320: 31973
B7321: 31974
B7322: 31975
...

Sheet 3. CONVEXITY_ANALYSIS
B1: DAILY RETURNS | L1: VARIABLE RETURN PERIOD ANALYSIS
N2: RETURN PERIOD VARIABLE (DAYS): | O2: 160
B4: RAW INDEX LEVELS | E4: INDEXED TO 100 | H4: % DAILY RETURNS | M4: INDEX LEVEL | P4: RETURNS | S4: SG RELATIVE RETURN
B5: 60/40 Equity/Bond | C5: SG Trend | D5: S&P | E5: 60/40 Equity/Bond | F5: SG Trend | G5: S&P | H5: 60/40 Equity/Bond | I5: SG Trend | J5: S&P | M5: 60/40 Equity/Bond | N5: SG Trend | O5: S&P | P5: 60/40 Equity/Bond | Q5: SG Trend | R5: S&P | S5: TO 60/40 | T5: TO S&P
A6: 46205 | B6: 1577.406 | C6: 100 | D6: 7528.25 | E6: =B6/B7*E7 -> 355.26799 | F6: =C6/C7*F7 -> 100 | G6: =D6/D7*G7 -> 431.46284 | H6: =E6/E7-1 -> -0.0012140409 | I6: =F6/F7-1 -> 0 | J6: =G6/G7-1 -> -0.002021608 | L6: {=_xlfn._xlws.FILTER(A6:A6716,MOD(ROW(A6:A6716)-ROW(A6),$O$2)=0)} -> 46205 | M6: =VLOOKUP($L6,$A:$G,5,FALSE) -> 355.26799 | N6: =VLOOKUP($L6,$A:$G,6,FALSE) -> 100 | O6: =VLOOKUP($L6,$A:$G,7,FALSE) -> 431.46284 | P6: =M6/M7-1 -> 0.031926767 | Q6: =N6/N7-1 -> 0 | R6: =O6/O7-1 -> 0.069083385 | S6: =Q6-P6 -> -0.031926767 | T6: =Q6-R6 -> -0.069083385
A7: 46204 | B7: 1579.3234 | C7: 100 | D7: 7543.5 | E7: =B7/B8*E8 -> 355.69982 | F7: =C7/C8*F8 -> 100 | G7: =D7/D8*G8 -> 432.33686 | H7: =E7/E8-1 -> -0.0015150656 | I7: =F7/F8-1 -> 0 | J7: =G7/G8-1 -> -0.00062928493 | L7: 45972 | M7: =VLOOKUP($L7,$A:$G,5,FALSE) -> 344.27636 | N7: =VLOOKUP($L7,$A:$G,6,FALSE) -> 100 | O7: =VLOOKUP($L7,$A:$G,7,FALSE) -> 403.58203 | P7: =M7/M8-1 -> 0.10307709 | Q7: =N7/N8-1 -> 0 | R7: =O7/O8-1 -> 0.158826 | S7: =Q7-P7 -> -0.10307709 | T7: =Q7-R7 -> -0.158826
A8: 46203 | B8: 1581.7198 | C8: 100 | D8: 7548.25 | E8: =B8/B9*E9 -> 356.23955 | F8: =C8/C9*F9 -> 100 | G8: =D8/D9*G9 -> 432.60909 | H8: =E8/E9-1 -> 0.0030390575 | I8: =F8/F9-1 -> 0 | J8: =G8/G9-1 -> 0.0063997867 | L8: 45741 | M8: =VLOOKUP($L8,$A:$G,5,FALSE) -> 312.10544 | N8: =VLOOKUP($L8,$A:$G,6,FALSE) -> 100 | O8: =VLOOKUP($L8,$A:$G,7,FALSE) -> 348.26802 | P8: =M8/M9-1 -> 0.033425455 | Q8: =N8/N9-1 -> 0 | R8: =O8/O9-1 -> 0.083313129 | S8: =Q8-P8 -> -0.033425455 | T8: =Q8-R8 -> -0.083313129
A9: 46202 | B9: 1576.9274 | C9: 100 | D9: 7500.25 | E9: =B9/B10*E10 -> 355.16019 | F9: =C9/C10*F10 -> 100 | G9: =D9/D10*G10 -> 429.85809 | H9: =E9/E10-1 -> 0.0080823868 | I9: =F9/F10-1 -> 0 | J9: =G9/G10-1 -> 0.013307664 | L9: 45509 | M9: =VLOOKUP($L9,$A:$G,5,FALSE) -> 302.01059 | N9: =VLOOKUP($L9,$A:$G,6,FALSE) -> 100 | O9: =VLOOKUP($L9,$A:$G,7,FALSE) -> 321.48416 | P9: =M9/M10-1 -> 0.049083278 | Q9: =N9/N10-1 -> 0 | R9: =O9/O10-1 -> 0.069309573 | S9: =Q9-P9 -> -0.049083278 | T9: =Q9-R9 -> -0.069309573
A10: 46199 | B10: 1564.2842 | C10: 100 | D10: 7401.75 | E10: =B10/B11*E11 -> 352.31267 | F10: =C10/C11*F11 -> 100 | G10: =D10/D11*G11 -> 424.21281 | H10: =E10/E11-1 -> -0.0012391908 | I10: =F10/F11-1 -> 0 | J10: =G10/G11-1 -> -0.0028963055 | L10: 45273 | M10: =VLOOKUP($L10,$A:$G,5,FALSE) -> 287.88048 | N10: =VLOOKUP($L10,$A:$G,6,FALSE) -> 100 | O10: =VLOOKUP($L10,$A:$G,7,FALSE) -> 300.64649 | P10: =M10/M11-1 -> 0.05805732 | Q10: =N10/N11-1 -> 0 | R10: =O10/O11-1 -> 0.13125201 | S10: =Q10-P10 -> -0.05805732 | T10: =Q10-R10 -> -0.13125201
A11: 46198 | B11: 1566.2251 | C11: 100 | D11: 7423.25 | E11: =B11/B12*E12 -> 352.74979 | F11: =C11/C12*F12 -> 100 | G11: =D11/D12*G12 -> 425.44503 | H11: =E11/E12-1 -> -0.00010657321 | I11: =F11/F12-1 -> 0 | J11: =G11/G12-1 -> -0.00067310605 | L11: 45042 | M11: =VLOOKUP($L11,$A:$G,5,FALSE) -> 272.08401 | N11: =VLOOKUP($L11,$A:$G,6,FALSE) -> 100 | O11: =VLOOKUP($L11,$A:$G,7,FALSE) -> 265.76438 | P11: =M11/M12-1 -> -0.0027339789 | Q11: =N11/N12-1 -> 0 | R11: =O11/O12-1 -> 0.0031476065 | S11: =Q11-P11 -> 0.0027339789 | T11: =Q11-R11 -> -0.0031476065
A12: 46197 | B12: 1566.392 | C12: 100 | D12: 7428.25 | E12: =B12/B13*E13 -> 352.78739 | F12: =C12/C13*F13 -> 100 | G12: =D12/D13*G13 -> 425.73159 | H12: =E12/E13-1 -> 0.0013292626 | I12: =F12/F13-1 -> 0 | J12: =G12/G13-1 -> -0.0012436975 | L12: 44811 | M12: =VLOOKUP($L12,$A:$G,5,FALSE) -> 272.82992 | N12: =VLOOKUP($L12,$A:$G,6,FALSE) -> 100 | O12: =VLOOKUP($L12,$A:$G,7,FALSE) -> 264.93048 | P12: =M12/M13-1 -> -0.10867333 | Q12: =N12/N13-1 -> 0 | R12: =O12/O13-1 -> -0.12842239 | S12: =Q12-P12 -> 0.10867333 | T12: =Q12-R12 -> 0.12842239
A13: 46196 | B13: 1564.3126 | C13: 100 | D13: 7437.5 | E13: =B13/B14*E14 -> 352.31906 | F13: =C13/C14*F14 -> 100 | G13: =D13/D14*G14 -> 426.26173 | H13: =E13/E14-1 -> -0.0082472095 | I13: =F13/F14-1 -> 0 | J13: =G13/G14-1 -> -0.013757666 | L13: 44579 | M13: =VLOOKUP($L13,$A:$G,5,FALSE) -> 306.09419 | N13: =VLOOKUP($L13,$A:$G,6,FALSE) -> 100 | O13: =VLOOKUP($L13,$A:$G,7,FALSE) -> 303.9666 | P13: =M13/M14-1 -> 0.048279693 | Q13: =N13/N14-1 -> 0 | R13: =O13/O14-1 -> 0.096039629 | S13: =Q13-P13 -> -0.048279693 | T13: =Q13-R13 -> -0.096039629
A14: 46195 | B14: 1577.3211 | C14: 100 | D14: 7541.25 | E14: =B14/B15*E15 -> 355.24888 | F14: =C14/C15*F15 -> 100 | G14: =D14/D15*G15 -> 432.20791 | H14: =E14/E15-1 -> -0.0037745287 | I14: =F14/F15-1 -> 0 | J14: =G14/G15-1 -> -0.0038965756 | L14: 44348 | M14: =VLOOKUP($L14,$A:$G,5,FALSE) -> 291.99668 | N14: =VLOOKUP($L14,$A:$G,6,FALSE) -> 100 | O14: =VLOOKUP($L14,$A:$G,7,FALSE) -> 277.33176 | P14: =M14/M15-1 -> 0.10021975 | Q14: =N14/N15-1 -> 0 | R14: =O14/O15-1 -> 0.19437239 | S14: =Q14-P14 -> -0.10021975 | T14: =Q14-R14 -> -0.19437239
A15: 46191 | B15: 1583.2973 | C15: 100 | D15: 7570.75 | E15: =B15/B16*E16 -> 356.59485 | F15: =C15/C16*F16 -> 100 | G15: =D15/D16*G16 -> 433.89863 | H15: =E15/E16-1 -> 0.0067845527 | I15: =F15/F16-1 -> 0 | J15: =G15/G16-1 -> 0.010410063 | L15: 44116 | M15: =VLOOKUP($L15,$A:$G,5,FALSE) -> 265.39851 | N15: =VLOOKUP($L15,$A:$G,6,FALSE) -> 100 | O15: =VLOOKUP($L15,$A:$G,7,FALSE) -> 232.19874 | P15: =M15/M16-1 -> 0.12069951 | Q15: =N15/N16-1 -> 0 | R15: =O15/O16-1 -> 0.14209642 | S15: =Q15-P15 -> -0.12069951 | T15: =Q15-R15 -> -0.14209642
A16: 46190 | B16: 1572.6278 | C16: 100 | D16: 7492.75 | E16: =B16/B17*E17 -> 354.19182 | F16: =C16/C17*F17 -> 100 | G16: =D16/D17*G17 -> 429.42825 | H16: =E16/E17-1 -> -0.0091716717 | I16: =F16/F17-1 -> 0 | J16: =G16/G17-1 -> -0.01250196 | L16: 43886 | M16: =VLOOKUP($L16,$A:$G,5,FALSE) -> 236.81505 | N16: =VLOOKUP($L16,$A:$G,6,FALSE) -> 100 | O16: =VLOOKUP($L16,$A:$G,7,FALSE) -> 203.30922 | P16: =M16/M17-1 -> 0.046533463 | Q16: =N16/N17-1 -> 0 | R16: =O16/O17-1 -> 0.049449298 | S16: =Q16-P16 -> -0.046533463 | T16: =Q16-R16 -> -0.049449298
A17: 46189 | B17: 1587.1849 | C17: 100 | D17: 7587.61 | E17: =B17/B18*E18 -> 357.47042 | F17: =C17/C18*F18 -> 100 | G17: =D17/D18*G18 -> 434.86491 | H17: =E17/E18-1 -> -0.0026593499 | I17: =F17/F18-1 -> 0 | J17: =G17/G18-1 -> -0.0056547447 | L17: 43654 | M17: =VLOOKUP($L17,$A:$G,5,FALSE) -> 226.28522 | N17: =VLOOKUP($L17,$A:$G,6,FALSE) -> 100 | O17: =VLOOKUP($L17,$A:$G,7,FALSE) -> 193.72944 | P17: =M17/M18-1 -> 0.093216846 | Q17: =N17/N18-1 -> 0 | R17: =O17/O18-1 -> 0.099995119 | S17: =Q17-P17 -> -0.093216846 | T17: =Q17-R17 -> -0.099995119
A18: 46188 | B18: 1591.417 | C18: 100 | D18: 7630.76 | E18: =B18/B19*E19 -> 358.4236 | F18: =C18/C19*F19 -> 100 | G18: =D18/D19*G19 -> 437.33795 | H18: =E18/E19-1 -> 0.011203652 | I18: =F18/F19-1 -> 0 | J18: =G18/G19-1 -> 0.016980415 | L18: 43418 | M18: =VLOOKUP($L18,$A:$G,5,FALSE) -> 206.99024 | N18: =VLOOKUP($L18,$A:$G,6,FALSE) -> 100 | O18: =VLOOKUP($L18,$A:$G,7,FALSE) -> 176.11845 | P18: =M18/M19-1 -> 0.005800462 | Q18: =N18/N19-1 -> 0 | R18: =O18/O19-1 -> 0.017172724 | S18: =Q18-P18 -> -0.005800462 | T18: =Q18-R18 -> -0.017172724 | AI18: TABLE
A19: 46185 | B19: 1573.7849 | C19: 100 | D19: 7503.35 | E19: =B19/B20*E20 -> 354.45243 | F19: =C19/C20*F20 -> 100 | G19: =D19/D20*G20 -> 430.03576 | H19: =E19/E20-1 -> 0.0027978066 | I19: =F19/F20-1 -> 0 | J19: =G19/G20-1 -> 0.005273319 | L19: 43188 | M19: =VLOOKUP($L19,$A:$G,5,FALSE) -> 205.79652 | N19: =VLOOKUP($L19,$A:$G,6,FALSE) -> 100 | O19: =VLOOKUP($L19,$A:$G,7,FALSE) -> 173.14508 | P19: =M19/M20-1 -> 0.026818842 | Q19: =N19/N20-1 -> 0 | R19: =O19/O20-1 -> 0.067044592 | S19: =Q19-P19 -> -0.026818842 | T19: =Q19-R19 -> -0.067044592 | AI19: VS s&p
A20: 46184 | B20: 1569.394 | C20: 100 | D20: 7463.99 | E20: =B20/B21*E21 -> 353.46351 | F20: =C20/C21*F21 -> 100 | G20: =D20/D21*G21 -> 427.77994 | H20: =E20/E21-1 -> 0.011946635 | I20: =F20/F21-1 -> 0 | J20: =G20/G21-1 -> 0.016143415 | L20: 42956 | M20: =VLOOKUP($L20,$A:$G,5,FALSE) -> 200.42145 | N20: =VLOOKUP($L20,$A:$G,6,FALSE) -> 100 | O20: =VLOOKUP($L20,$A:$G,7,FALSE) -> 162.26602 | P20: =M20/M21-1 -> 0.070323789 | Q20: =N20/N21-1 -> 0 | R20: =O20/O21-1 -> 0.096988295 | S20: =Q20-P20 -> -0.070323789 | T20: =Q20-R20 -> -0.096988295 | AI20: {=_xlfn.LET(_xlpm.x,_xlfn._xlws.FILTER(R6:R6716,ISNUMBER(R6:R6716)*ISNUMBER(Q6:Q6716)),_xlpm.y,_xlfn._xlws.FILTER(Q6:Q6716,ISNUMBER(R6:R6716)*ISNUMBER(Q6:Q6716)),INDEX(LINEST(_xlpm.y,_xlpm.x^{1,2}),1,1))} -> 0
A21: 46183 | B21: 1550.8664 | C21: 100 | D21: 7345.41 | E21: =B21/B22*E22 -> 349.29066 | F21: =C21/C22*F22 -> 100 | G21: =D21/D22*G22 -> 420.98383 | H21: =E21/E22-1 -> -0.010019636 | I21: =F21/F22-1 -> 0 | J21: =G21/G22-1 -> -0.015454293 | L21: 42723 | M21: =VLOOKUP($L21,$A:$G,5,FALSE) -> 187.25311 | N21: =VLOOKUP($L21,$A:$G,6,FALSE) -> 100 | O21: =VLOOKUP($L21,$A:$G,7,FALSE) -> 147.91956 | P21: =M21/M22-1 -> 0.048018576 | Q21: =N21/N22-1 -> 0 | R21: =O21/O22-1 -> 0.10939508 | S21: =Q21-P21 -> -0.048018576 | T21: =Q21-R21 -> -0.10939508 | AH21: 1 | AI21: 0
A22: 46182 | B22: 1566.5628 | C22: 100 | D22: 7460.71 | E22: =B22/B23*E23 -> 352.82585 | F22: =C22/C23*F23 -> 100 | G22: =D22/D23*G23 -> 427.59196 | H22: =E22/E23-1 -> -0.0013501892 | I22: =F22/F23-1 -> 0 | J22: =G22/G23-1 -> -0.0031346161 | L22: 42493 | M22: =VLOOKUP($L22,$A:$G,5,FALSE) -> 178.67346 | N22: =VLOOKUP($L22,$A:$G,6,FALSE) -> 100 | O22: =VLOOKUP($L22,$A:$G,7,FALSE) -> 133.33352 | P22: =M22/M23-1 -> 0.054017367 | Q22: =N22/N23-1 -> 0 | R22: =O22/O23-1 -> 0.068242868 | S22: =Q22-P22 -> -0.054017367 | T22: =Q22-R22 -> -0.068242868 | AH22: 10 | AI22: 0
A23: 46181 | B23: 1568.6808 | C23: 100 | D23: 7484.17 | E23: =B23/B24*E24 -> 353.30288 | F23: =C23/C24*F24 -> 100 | G23: =D23/D24*G24 -> 428.93651 | H23: =E23/E24-1 -> 0.0011648783 | I23: =F23/F24-1 -> 0 | J23: =G23/G24-1 -> 0.0020941203 | L23: 42261 | M23: =VLOOKUP($L23,$A:$G,5,FALSE) -> 169.51662 | N23: =VLOOKUP($L23,$A:$G,6,FALSE) -> 100 | O23: =VLOOKUP($L23,$A:$G,7,FALSE) -> 124.81574 | P23: =M23/M24-1 -> -0.01806987 | Q23: =N23/N24-1 -> 0 | R23: =O23/O24-1 -> -0.029505085 | S23: =Q23-P23 -> 0.01806987 | T23: =Q23-R23 -> 0.029505085 | AH23: 20 | AI23: 0
A24: 46178 | B24: 1566.8556 | C24: 100 | D24: 7468.53 | E24: =B24/B25*E25 -> 352.8918 | F24: =C24/C25*F25 -> 100 | G24: =D24/D25*G25 -> 428.04014 | H24: =E24/E25-1 -> -0.01850881 | I24: =F24/F25-1 -> 0 | J24: =G24/G25-1 -> -0.026377712 | L24: 42031 | M24: =VLOOKUP($L24,$A:$G,5,FALSE) -> 172.63613 | N24: =VLOOKUP($L24,$A:$G,6,FALSE) -> 100 | O24: =VLOOKUP($L24,$A:$G,7,FALSE) -> 128.6104 | P24: =M24/M25-1 -> 0.052855885 | Q24: =N24/N25-1 -> 0 | R24: =O24/O25-1 -> 0.051881088 | S24: =Q24-P24 -> -0.052855885 | T24: =Q24-R24 -> -0.051881088 | AH24: 30 | AI24: 0
A25: 46177 | B25: 1596.4031 | C25: 100 | D25: 7670.87 | E25: =B25/B26*E26 -> 359.54658 | F25: =C25/C26*F26 -> 100 | G25: =D25/D26*G26 -> 439.63675 | H25: =E25/E26-1 -> 0.0029255025 | I25: =F25/F26-1 -> 0 | J25: =G25/G26-1 -> 0.0038631917 | L25: 41799 | M25: =VLOOKUP($L25,$A:$G,5,FALSE) -> 163.96938 | N25: =VLOOKUP($L25,$A:$G,6,FALSE) -> 100 | O25: =VLOOKUP($L25,$A:$G,7,FALSE) -> 122.26705 | P25: =M25/M26-1 -> 0.085047289 | Q25: =N25/N26-1 -> 0 | R25: =O25/O26-1 -> 0.13755686 | S25: =Q25-P25 -> -0.085047289 | T25: =Q25-R25 -> -0.13755686 | AH25: 40 | AI25: 0
A26: 46176 | B26: 1591.7465 | C26: 100 | D26: 7641.35 | E26: =B26/B27*E27 -> 358.49779 | F26: =C26/C27*F27 -> 100 | G26: =D26/D27*G27 -> 437.94489 | H26: =E26/E27-1 -> -0.005173984 | I26: =F26/F27-1 -> 0 | J26: =G26/G27-1 -> -0.0068210501 | L26: 41564 | M26: =VLOOKUP($L26,$A:$G,5,FALSE) -> 151.11727 | N26: =VLOOKUP($L26,$A:$G,6,FALSE) -> 100 | O26: =VLOOKUP($L26,$A:$G,7,FALSE) -> 107.48215 | P26: =M26/M27-1 -> 0.081749199 | Q26: =N26/N27-1 -> 0 | R26: =O26/O27-1 -> 0.15308751 | S26: =Q26-P26 -> -0.081749199 | T26: =Q26-R26 -> -0.15308751 | AH26: 50 | AI26: 0
A27: 46175 | B27: 1600.025 | C27: 100 | D27: 7693.83 | E27: =B27/B28*E28 -> 360.3623 | F27: =C27/C28*F28 -> 100 | G27: =D27/D28*G28 -> 440.95265 | H27: =E27/E28-1 -> 0.0011886079 | I27: =F27/F28-1 -> 0 | J27: =G27/G28-1 -> 0.0013783248 | L27: 41334 | M27: =VLOOKUP($L27,$A:$G,5,FALSE) -> 139.69714 | N27: =VLOOKUP($L27,$A:$G,6,FALSE) -> 100 | O27: =VLOOKUP($L27,$A:$G,7,FALSE) -> 93.21248 | P27: =M27/M28-1 -> 0.087814537 | Q27: =N27/N28-1 -> 0 | R27: =O27/O28-1 -> 0.15014815 | S27: =Q27-P27 -> -0.087814537 | T27: =Q27-R27 -> -0.15014815 | AH27: 60 | AI27: 0
A28: 46174 | B28: 1598.1254 | C28: 100 | D28: 7683.24 | E28: =B28/B29*E29 -> 359.93448 | F28: =C28/C29*F29 -> 100 | G28: =D28/D29*G29 -> 440.34571 | H28: =E28/E29-1 -> 0.00074221167 | I28: =F28/F29-1 -> 0 | J28: =G28/G29-1 -> 0.0023051123 | L28: 41102 | M28: =VLOOKUP($L28,$A:$G,5,FALSE) -> 128.42 | N28: =VLOOKUP($L28,$A:$G,6,FALSE) -> 100 | O28: =VLOOKUP($L28,$A:$G,7,FALSE) -> 81.04389 | P28: =M28/M29-1 -> 0.1052656 | Q28: =N28/N29-1 -> 0 | R28: =O28/O29-1 -> 0.14008482 | S28: =Q28-P28 -> -0.1052656 | T28: =Q28-R28 -> -0.14008482 | AH28: 70 | AI28: 0
A29: 46171 | B29: 1596.9402 | C29: 100 | D29: 7665.57 | E29: =B29/B30*E30 -> 359.66753 | F29: =C29/C30*F30 -> 100 | G29: =D29/D30*G30 -> 439.333 | H29: =E29/E30-1 -> 0.0012771328 | I29: =F29/F30-1 -> 0 | J29: =G29/G30-1 -> 0.0018454019 | L29: 40869 | M29: =VLOOKUP($L29,$A:$G,5,FALSE) -> 116.18927 | N29: =VLOOKUP($L29,$A:$G,6,FALSE) -> 100 | O29: =VLOOKUP($L29,$A:$G,7,FALSE) -> 71.085843 | P29: =M29/M30-1 -> -0.010452026 | Q29: =N29/N30-1 -> 0 | R29: =O29/O30-1 -> -0.10134763 | S29: =Q29-P29 -> 0.010452026 | T29: =Q29-R29 -> 0.10134763 | AH29: 80 | AI29: 0
A30: 46170 | B30: 1594.9033 | C30: 100 | D30: 7651.45 | E30: =B30/B31*E31 -> 359.20877 | F30: =C30/C31*F31 -> 100 | G30: =D30/D31*G31 -> 438.52374 | H30: =E30/E31-1 -> 0.0039843663 | I30: =F30/F31-1 -> 0 | J30: =G30/G31-1 -> 0.0055379528 | L30: 40639 | M30: =VLOOKUP($L30,$A:$G,5,FALSE) -> 117.41651 | N30: =VLOOKUP($L30,$A:$G,6,FALSE) -> 100 | O30: =VLOOKUP($L30,$A:$G,7,FALSE) -> 79.102715 | P30: =M30/M31-1 -> 0.12481311 | Q30: =N30/N31-1 -> 0 | R30: =O30/O31-1 -> 0.23844732 | S30: =Q30-P30 -> -0.12481311 | T30: =Q30-R30 -> -0.23844732 | AH30: 90 | AI30: 0
A31: 46169 | B31: 1588.5738 | C31: 100 | D31: 7609.31 | E31: =B31/B32*E32 -> 357.78324 | F31: =C31/C32*F32 -> 100 | G31: =D31/D32*G32 -> 436.1086 | H31: =E31/E32-1 -> 0.00051318687 | I31: =F31/F32-1 -> 0 | J31: =G31/G32-1 -> 0.00039835504 | L31: 40408 | M31: =VLOOKUP($L31,$A:$G,5,FALSE) -> 104.38757 | N31: =VLOOKUP($L31,$A:$G,6,FALSE) -> 100 | O31: =VLOOKUP($L31,$A:$G,7,FALSE) -> 63.872491 | P31: =M31/M32-1 -> 0.030981892 | Q31: =N31/N32-1 -> 0 | R31: =O31/O32-1 -> -0.023294538 | S31: =Q31-P31 -> -0.030981892 | T31: =Q31-R31 -> 0.023294538 | AH31: 100 | AI31: 0
A32: 46168 | B32: 1587.759 | C32: 100 | D32: 7606.28 | E32: =B32/B33*E33 -> 357.59972 | F32: =C32/C33*F33 -> 100 | G32: =D32/D33*G33 -> 435.93494 | H32: =E32/E33-1 -> 0.0058348674 | I32: =F32/F33-1 -> 0 | J32: =G32/G33-1 -> 0.0061403253 | L32: 40176 | M32: =VLOOKUP($L32,$A:$G,5,FALSE) -> 101.25063 | N32: =VLOOKUP($L32,$A:$G,6,FALSE) -> 100 | O32: =VLOOKUP($L32,$A:$G,7,FALSE) -> 65.395857 | P32: =M32/M33-1 -> 0.144404 | Q32: =N32/N33-1 -> 0 | R32: =O32/O33-1 -> 0.25417954 | S32: =Q32-P32 -> -0.144404 | T32: =Q32-R32 -> -0.25417954 | AH32: 110 | AI32: 0
... A46: 46147 | B46: 1557.0777 | C46: 100 | D46: 7354.24 | E46: =B46/B47*E47 -> 350.68959 | F46: =C46/C47*F47 -> 100 | G46: =D46/D47*G47 -> 421.4899 | H46: =E46/E47-1 -> 0.0055114413 | I46: =F46/F47-1 -> 0 | J46: =G46/G47-1 -> 0.0078843753 | L46: 36966 | M46: =VLOOKUP($L46,$A:$G,5,FALSE) -> 87.425555 | N46: =VLOOKUP($L46,$A:$G,6,FALSE) -> 100 | O46: =VLOOKUP($L46,$A:$G,7,FALSE) -> 73.171445 | P46: =M46/M47-1 -> -0.11441408 | Q46: =N46/N47-1 -> 0 | R46: =O46/O47-1 -> -0.23096708 | S46: =Q46-P46 -> 0.11441408 | T46: =Q46-R46 -> 0.23096708 | AH46: 250 | AI46: 0
A47: 46146 | B47: 1548.543 | C47: 100 | D47: 7296.71 | E47: =B47/B48*E48 -> 348.76738 | F47: =C47/C48*F48 -> 100 | G47: =D47/D48*G48 -> 418.19271 | H47: =E47/E48-1 -> -0.0039825986 | I47: =F47/F48-1 -> 0 | J47: =G47/G48-1 -> -0.003824037 | L47: 36740 | M47: =VLOOKUP($L47,$A:$G,5,FALSE) -> 98.720579 | N47: =VLOOKUP($L47,$A:$G,6,FALSE) -> 100 | O47: =VLOOKUP($L47,$A:$G,7,FALSE) -> 95.14735 | P47: =M47/M48-1 -> #N/A | Q47: =N47/N48-1 -> #N/A | R47: =O47/O48-1 -> #N/A | S47: =Q47-P47 -> #N/A | T47: =Q47-R47 -> #N/A
A48: 46143 | B48: 1554.7349 | C48: 100 | D48: 7324.72 | E48: =B48/B49*E49 -> 350.16193 | F48: =C48/C49*F49 -> 100 | G48: =D48/D49*G49 -> 419.79803 | H48: =E48/E49-1 -> 0.0013873698 | I48: =F48/F49-1 -> 0 | J48: =G48/G49-1 -> 0.0019670768 | M48: =VLOOKUP($L48,$A:$G,5,FALSE) -> #N/A | N48: =VLOOKUP($L48,$A:$G,6,FALSE) -> #N/A | O48: =VLOOKUP($L48,$A:$G,7,FALSE) -> #N/A | P48: =M48/M49-1 -> #N/A | Q48: =N48/N49-1 -> #N/A | R48: =O48/O49-1 -> #N/A | S48: =Q48-P48 -> #N/A | T48: =Q48-R48 -> #N/A
A49: 46142 | B49: 1552.5809 | C49: 100 | D49: 7310.34 | E49: =B49/B50*E50 -> 349.6768 | F49: =C49/C50*F50 -> 100 | G49: =D49/D50*G50 -> 418.97388 | H49: =E49/E50-1 -> 0.0073793616 | I49: =F49/F50-1 -> 0 | J49: =G49/G50-1 -> 0.010568311 | M49: =VLOOKUP($L49,$A:$G,5,FALSE) -> #N/A | N49: =VLOOKUP($L49,$A:$G,6,FALSE) -> #N/A | O49: =VLOOKUP($L49,$A:$G,7,FALSE) -> #N/A | P49: =M49/M50-1 -> #N/A | Q49: =N49/N50-1 -> #N/A | R49: =O49/O50-1 -> #N/A | S49: =Q49-P49 -> #N/A | T49: =Q49-R49 -> #N/A
A50: 46141 | B50: 1541.2078 | C50: 100 | D50: 7233.89 | E50: =B50/B51*E51 -> 347.11531 | F50: =C50/C51*F51 -> 100 | G50: =D50/D51*G51 -> 414.59234 | H50: =E50/E51-1 -> -0.0019724863 | I50: =F50/F51-1 -> 0 | J50: =G50/G51-1 -> -0.0004186864 | M50: =VLOOKUP($L50,$A:$G,5,FALSE) -> #N/A | N50: =VLOOKUP($L50,$A:$G,6,FALSE) -> #N/A | O50: =VLOOKUP($L50,$A:$G,7,FALSE) -> #N/A | P50: =M50/M51-1 -> #N/A | Q50: =N50/N51-1 -> #N/A | R50: =O50/O51-1 -> #N/A | S50: =Q50-P50 -> #N/A | T50: =Q50-R50 -> #N/A
A51: 46140 | B51: 1544.2538 | C51: 100 | D51: 7236.92 | E51: =B51/B52*E52 -> 347.80135 | F51: =C51/C52*F52 -> 100 | G51: =D51/D52*G52 -> 414.76599 | H51: =E51/E52-1 -> -0.0036072858 | I51: =F51/F52-1 -> 0 | J51: =G51/G52-1 -> -0.0048568254 | M51: =VLOOKUP($L51,$A:$G,5,FALSE) -> #N/A | N51: =VLOOKUP($L51,$A:$G,6,FALSE) -> #N/A | O51: =VLOOKUP($L51,$A:$G,7,FALSE) -> #N/A | P51: =M51/M52-1 -> #N/A | Q51: =N51/N52-1 -> #N/A | R51: =O51/O52-1 -> #N/A | S51: =Q51-P51 -> #N/A | T51: =Q51-R51 -> #N/A
A52: 46139 | B52: 1549.8445 | C52: 100 | D52: 7272.24 | E52: =B52/B53*E53 -> 349.06051 | F52: =C52/C53*F53 -> 100 | G52: =D52/D53*G53 -> 416.79027 | H52: =E52/E53-1 -> 0.00033099146 | I52: =F52/F53-1 -> 0 | J52: =G52/G53-1 -> 0.0015631693 | M52: =VLOOKUP($L52,$A:$G,5,FALSE) -> #N/A | N52: =VLOOKUP($L52,$A:$G,6,FALSE) -> #N/A | O52: =VLOOKUP($L52,$A:$G,7,FALSE) -> #N/A | P52: =M52/M53-1 -> #N/A | Q52: =N52/N53-1 -> #N/A | R52: =O52/O53-1 -> #N/A | S52: =Q52-P52 -> #N/A | T52: =Q52-R52 -> #N/A
A53: 46136 | B53: 1549.3317 | C53: 100 | D53: 7260.89 | E53: =B53/B54*E54 -> 348.94501 | F53: =C53/C54*F54 -> 100 | G53: =D53/D54*G54 -> 416.13977 | H53: =E53/E54-1 -> 0.0050368089 | I53: =F53/F54-1 -> 0 | J53: =G53/G54-1 -> 0.0071741962 | M53: =VLOOKUP($L53,$A:$G,5,FALSE) -> #N/A | N53: =VLOOKUP($L53,$A:$G,6,FALSE) -> #N/A | O53: =VLOOKUP($L53,$A:$G,7,FALSE) -> #N/A | P53: =M53/M54-1 -> #N/A | Q53: =N53/N54-1 -> #N/A | R53: =O53/O54-1 -> #N/A | S53: =Q53-P53 -> #N/A | T53: =Q53-R53 -> #N/A
A54: 46135 | B54: 1541.5671 | C54: 100 | D54: 7209.17 | E54: =B54/B55*E55 -> 347.19625 | F54: =C54/C55*F55 -> 100 | G54: =D54/D55*G55 -> 413.17557 | H54: =E54/E55-1 -> -0.0032013868 | I54: =F54/F55-1 -> 0 | J54: =G54/G55-1 -> -0.0038689156 | M54: =VLOOKUP($L54,$A:$G,5,FALSE) -> #N/A | N54: =VLOOKUP($L54,$A:$G,6,FALSE) -> #N/A | O54: =VLOOKUP($L54,$A:$G,7,FALSE) -> #N/A | P54: =M54/M55-1 -> #N/A | Q54: =N54/N55-1 -> #N/A | R54: =O54/O55-1 -> #N/A | S54: =Q54-P54 -> #N/A | T54: =Q54-R54 -> #N/A
...
